
#######################################################################
# +-----------------------------------------------------------------+ #
# |                            BO3 object                           | #
# +-----------------------------------------------------------------+ #
#######################################################################

Author: MC_Pitman

Description: No description given

Version: 3

SettingsMode: WriteWithoutComments


#######################################################################
# +-----------------------------------------------------------------+ #
# |                          Main settings                          | #
# +-----------------------------------------------------------------+ #
#######################################################################

Tree: true

Frequency: 1

Rarity: 100.0

RotateRandomly: true

SpawnHeight: highestSolidBlock

SpawnHeightOffset: 0

SpawnHeightVariance: 0

##############################
# Height Limits for the BO3. #
##############################

MinHeight: 63

MaxHeight: 130

######################
# Extrusion settings #
######################

ExtrudeMode: None

ExtrudeThroughBlocks: AIR

MaxBranchDepth: 10

ExcludedBiomes: All


#######################################################################
# +-----------------------------------------------------------------+ #
# |                      Source block settings                      | #
# +-----------------------------------------------------------------+ #
#######################################################################

SourceBlocks: AIR

MaxPercentageOutsideSourceBlock: 0

OutsideSourceBlock: placeAnyway

IsOTGPlus: false


#######################################################################
# +-----------------------------------------------------------------+ #
# |                              Blocks                             | #
# +-----------------------------------------------------------------+ #
#######################################################################

Block(-3,10,-1,LEAVES:13)
Block(-3,13,0,LEAVES:13)
Block(-3,15,0,LEAVES:13)
Block(-2,8,-1,LEAVES:13)
Block(-2,9,1,LEAVES:13)
Block(-2,11,-1,LEAVES:13)
Block(-2,11,2,LEAVES:13)
Block(-2,12,1,LEAVES:13)
Block(-2,13,0,LEAVES:13)
Block(-2,15,-2,LEAVES:13)
Block(-2,15,-1,LEAVES:13)
Block(-2,15,0,LOG:13)
Block(-2,15,1,LEAVES:13)
Block(-2,16,0,LEAVES:13)
Block(-2,19,-1,LEAVES:13)
Block(-1,8,-2,LEAVES:13)
Block(-1,8,-1,LEAVES:13)
Block(-1,8,2,LEAVES:13)
Block(-1,9,0,LEAVES:13)
Block(-1,9,1,LEAVES:13)
Block(-1,11,0,LEAVES:13)
Block(-1,12,2,LEAVES:13)
Block(-1,13,-2,LEAVES:13)
Block(-1,13,-1,LEAVES:13)
Block(-1,13,0,LEAVES:13)
Block(-1,14,0,LEAVES:13)
Block(-1,16,-1,LEAVES:13)
Block(-1,16,0,LOG:13)
Block(-1,17,0,LEAVES:13)
Block(-1,17,1,LEAVES:13)
Block(-1,19,0,LEAVES:13)
Block(-1,20,-1,LEAVES:13)
Block(-1,21,0,LEAVES:13)
Block(0,0,0,LOG:13)
Block(0,1,0,LOG:13)
Block(0,2,0,LOG:13)
Block(0,3,0,LOG:13)
Block(0,4,0,LOG:13)
Block(0,5,0,LOG:13)
Block(0,6,-1,LEAVES:13)
Block(0,6,0,LOG:13)
Block(0,7,0,LOG:13)
Block(0,7,1,LEAVES:13)
Block(0,8,-2,LEAVES:13)
Block(0,8,-1,LEAVES:13)
Block(0,8,0,LOG:13)
Block(0,8,2,LOG:13)
Block(0,8,3,LEAVES:13)
Block(0,9,0,LOG:13)
Block(0,9,1,LOG:13)
Block(0,9,2,LEAVES:13)
Block(0,10,-2,LEAVES:13)
Block(0,10,-1,LEAVES:13)
Block(0,10,0,LOG:13)
Block(0,10,1,LEAVES:13)
Block(0,11,0,LOG:13)
Block(0,12,-1,LEAVES:13)
Block(0,12,0,LOG:13)
Block(0,12,1,LEAVES:13)
Block(0,12,2,LEAVES:13)
Block(0,12,3,LEAVES:13)
Block(0,13,-3,LEAVES:13)
Block(0,13,-2,LEAVES:13)
Block(0,13,-1,LEAVES:13)
Block(0,13,0,LOG:13)
Block(0,13,1,LEAVES:13)
Block(0,14,0,LOG:13)
Block(0,15,-3,LEAVES:13)
Block(0,15,-2,LEAVES:13)
Block(0,15,-1,LEAVES:13)
Block(0,15,0,LOG:13)
Block(0,15,1,LEAVES:13)
Block(0,16,0,LOG:13)
Block(0,17,-2,LEAVES:13)
Block(0,17,-1,LEAVES:13)
Block(0,17,0,LOG:13)
Block(0,17,1,LEAVES:13)
Block(0,17,2,LEAVES:13)
Block(0,18,0,LOG:13)
Block(0,18,1,LEAVES:13)
Block(0,19,-1,LEAVES:13)
Block(0,19,0,LOG:13)
Block(0,20,-2,LEAVES:13)
Block(0,20,-1,LOG:13)
Block(0,20,0,LOG:13)
Block(0,21,-1,LEAVES:13)
Block(0,21,0,LOG:13)
Block(0,21,1,LEAVES:13)
Block(0,22,0,LEAVES:13)
Block(1,7,0,LEAVES:13)
Block(1,8,-1,LEAVES:13)
Block(1,8,0,LEAVES:13)
Block(1,9,-2,LEAVES:13)
Block(1,9,0,LEAVES:13)
Block(1,9,1,LEAVES:13)
Block(1,10,-1,LEAVES:13)
Block(1,13,-1,LEAVES:13)
Block(1,13,0,LOG:13)
Block(1,13,1,LEAVES:13)
Block(1,15,-2,LEAVES:13)
Block(1,15,-1,LEAVES:13)
Block(1,15,0,LEAVES:13)
Block(1,15,1,LEAVES:13)
Block(1,15,2,LEAVES:13)
Block(1,16,-1,LEAVES:13)
Block(1,17,0,LEAVES:13)
Block(1,17,1,LEAVES:13)
Block(1,18,-1,LEAVES:13)
Block(1,19,-2,LEAVES:13)
Block(1,19,0,LEAVES:13)
Block(1,20,-1,LEAVES:13)
Block(1,20,0,LEAVES:13)
Block(2,8,-1,LEAVES:13)
Block(2,8,1,LEAVES:13)
Block(2,10,0,LEAVES:13)
Block(2,12,-1,LEAVES:13)
Block(2,12,0,LOG:13)
Block(2,12,1,LEAVES:13)
Block(2,13,0,LEAVES:13)
Block(2,15,0,LEAVES:13)
Block(2,17,0,LEAVES:13)
Block(2,19,0,LEAVES:13)
Block(3,12,0,LEAVES:13)
Block(3,14,-1,LEAVES:13)

#######################################################################
# +-----------------------------------------------------------------+ #
# |                            BO3 checks                           | #
# +-----------------------------------------------------------------+ #
#######################################################################


#######################################################################
# +-----------------------------------------------------------------+ #
# |                             Branches                            | #
# +-----------------------------------------------------------------+ #
#######################################################################


#######################################################################
# +-----------------------------------------------------------------+ #
# |                             Entities                            | #
# +-----------------------------------------------------------------+ #
#######################################################################


#######################################################################
# +-----------------------------------------------------------------+ #
# |                            Particles                            | #
# +-----------------------------------------------------------------+ #
#######################################################################


#######################################################################
# +-----------------------------------------------------------------+ #
# |                             Spawners                            | #
# +-----------------------------------------------------------------+ #
#######################################################################


#######################################################################
# +-----------------------------------------------------------------+ #
# |                             ModData                             | #
# +-----------------------------------------------------------------+ #
#######################################################################

