
#######################################################################
# +-----------------------------------------------------------------+ #
# |                            BO3 object                           | #
# +-----------------------------------------------------------------+ #
#######################################################################

Author: Unknown

Description: Converted version of the BO2 JunglePalm1

Version: 3

SettingsMode: WriteWithoutComments


#######################################################################
# +-----------------------------------------------------------------+ #
# |                          Main settings                          | #
# +-----------------------------------------------------------------+ #
#######################################################################

Tree: true

Frequency: 1

Rarity: 4.0

RotateRandomly: true

SpawnHeight: highestSolidBlock

SpawnHeightOffset: 0

SpawnHeightVariance: 0

##############################
# Height Limits for the BO3. #
##############################

MinHeight: 62

MaxHeight: 65

######################
# Extrusion settings #
######################

ExtrudeMode: None

ExtrudeThroughBlocks: AIR

MaxBranchDepth: 10

ExcludedBiomes: All


#######################################################################
# +-----------------------------------------------------------------+ #
# |                      Source block settings                      | #
# +-----------------------------------------------------------------+ #
#######################################################################

SourceBlocks: AIR

MaxPercentageOutsideSourceBlock: 0

OutsideSourceBlock: placeAnyway

DoReplaceBlocks: true

IsOTGPlus: false


#######################################################################
# +-----------------------------------------------------------------+ #
# |                              Blocks                             | #
# +-----------------------------------------------------------------+ #
#######################################################################

Block(3,8,-3,biomesoplenty:leaves_4:1)
Block(1,9,0,biomesoplenty:leaves_4:1)
Block(0,5,2,biomesoplenty:leaves_4:1)
Block(1,8,0,biomesoplenty:leaves_4:1)
Block(0,7,-4,biomesoplenty:leaves_4:1)
Block(1,7,0,COCOA:9)
Block(2,9,2,biomesoplenty:leaves_4:1)
Block(2,8,2,biomesoplenty:leaves_4:1)
Block(-3,7,0,biomesoplenty:leaves_4:1)
Block(-3,8,0,biomesoplenty:leaves_4:1)
Block(0,10,1,biomesoplenty:leaves_4:1)
Block(-1,5,0,biomesoplenty:leaves_4:1)
Block(3,8,0,biomesoplenty:leaves_4:1)
Block(3,7,0,biomesoplenty:leaves_4:1)
Block(-1,6,0,biomesoplenty:leaves_4:1)
Block(-1,9,0,biomesoplenty:leaves_4:1)
Block(-1,8,0,biomesoplenty:leaves_4:1)
Block(-2,9,2,biomesoplenty:leaves_4:1)
Block(-2,8,2,biomesoplenty:leaves_4:1)
Block(0,8,3,biomesoplenty:leaves_4:1)
Block(0,7,3,biomesoplenty:leaves_4:1)
Block(0,5,-1,biomesoplenty:leaves_4:1)
Block(0,7,-1,COCOA:8)
Block(0,6,-1,biomesoplenty:leaves_4:1)
Block(0,9,-1,biomesoplenty:leaves_4:1)
Block(1,9,1,biomesoplenty:leaves_4:1)
Block(0,8,-1,biomesoplenty:leaves_4:1)
Block(1,8,1,biomesoplenty:leaves_4:1)
Block(0,6,1,biomesoplenty:leaves_4:1)
Block(0,5,1,biomesoplenty:leaves_4:1)
Block(-3,8,3,biomesoplenty:leaves_4:1)
Block(1,6,0,biomesoplenty:leaves_4:1)
Block(1,5,0,biomesoplenty:leaves_4:1)
Block(0,9,2,biomesoplenty:leaves_4:1)
Block(0,10,-1,biomesoplenty:leaves_4:1)
Block(1,3,0,biomesoplenty:log_1:15)
Block(0,8,2,biomesoplenty:leaves_4:1)
Block(1,2,0,biomesoplenty:log_1:15)
Block(0,10,0,biomesoplenty:leaves_4:1)
Block(0,3,0,biomesoplenty:log_1:15)
Block(0,5,-2,biomesoplenty:leaves_4:1)
Block(0,5,0,biomesoplenty:log_1:15)
Block(0,8,-2,biomesoplenty:leaves_4:1)
Block(0,4,0,biomesoplenty:log_1:15)
Block(0,7,0,biomesoplenty:log_1:15)
Block(0,6,0,biomesoplenty:log_1:15)
Block(0,9,-2,biomesoplenty:leaves_4:1)
Block(-4,7,0,biomesoplenty:leaves_4:1)
Block(2,9,0,biomesoplenty:leaves_4:1)
Block(2,8,0,biomesoplenty:leaves_4:1)
Block(-1,5,-1,biomesoplenty:leaves_4:1)
Block(-2,9,0,biomesoplenty:leaves_4:1)
Block(1,10,0,biomesoplenty:leaves_4:1)
Block(-2,8,0,biomesoplenty:leaves_4:1)
Block(-2,5,0,biomesoplenty:leaves_4:1)
Block(-1,9,-1,biomesoplenty:leaves_4:1)
Block(-1,8,-1,biomesoplenty:leaves_4:1)
Block(4,7,0,biomesoplenty:leaves_4:1)
Block(1,5,1,biomesoplenty:leaves_4:1)
Block(0,8,1,biomesoplenty:leaves_4:1)
Block(0,9,1,biomesoplenty:leaves_4:1)
Block(-1,10,0,biomesoplenty:leaves_4:1)
Block(0,7,-3,biomesoplenty:leaves_4:1)
Block(0,8,-3,biomesoplenty:leaves_4:1)
Block(-2,9,-2,biomesoplenty:leaves_4:1)
Block(1,9,-1,biomesoplenty:leaves_4:1)
Block(-2,8,-2,biomesoplenty:leaves_4:1)
Block(1,8,-1,biomesoplenty:leaves_4:1)
Block(1,5,-1,biomesoplenty:leaves_4:1)
Block(-1,5,1,biomesoplenty:leaves_4:1)
Block(-1,8,1,biomesoplenty:leaves_4:1)
Block(3,8,3,biomesoplenty:leaves_4:1)
Block(-1,9,1,biomesoplenty:leaves_4:1)
Block(2,2,0,biomesoplenty:log_1:15)
Block(2,5,0,biomesoplenty:leaves_4:1)
Block(2,1,0,biomesoplenty:log_1:15)
Block(2,0,0,biomesoplenty:log_1:15)
Block(-3,8,-3,biomesoplenty:leaves_4:1)
Block(2,8,-2,biomesoplenty:leaves_4:1)
Block(0,9,0,biomesoplenty:leaves_4:1)
Block(0,8,0,biomesoplenty:log_1:15)
Block(0,7,4,biomesoplenty:leaves_4:1)
Block(2,9,-2,biomesoplenty:leaves_4:1)

#######################################################################
# +-----------------------------------------------------------------+ #
# |                            BO3 checks                           | #
# +-----------------------------------------------------------------+ #
#######################################################################


#######################################################################
# +-----------------------------------------------------------------+ #
# |                             Branches                            | #
# +-----------------------------------------------------------------+ #
#######################################################################


#######################################################################
# +-----------------------------------------------------------------+ #
# |                             Entities                            | #
# +-----------------------------------------------------------------+ #
#######################################################################


#######################################################################
# +-----------------------------------------------------------------+ #
# |                            Particles                            | #
# +-----------------------------------------------------------------+ #
#######################################################################


#######################################################################
# +-----------------------------------------------------------------+ #
# |                             Spawners                            | #
# +-----------------------------------------------------------------+ #
#######################################################################


#######################################################################
# +-----------------------------------------------------------------+ #
# |                             ModData                             | #
# +-----------------------------------------------------------------+ #
#######################################################################

