
#######################################################################
# +-----------------------------------------------------------------+ #
# |                            BO3 object                           | #
# +-----------------------------------------------------------------+ #
#######################################################################

Author: Unknown

Description: Converted version of the BO2 JunglePalm2

Version: 3

SettingsMode: WriteWithoutComments


#######################################################################
# +-----------------------------------------------------------------+ #
# |                          Main settings                          | #
# +-----------------------------------------------------------------+ #
#######################################################################

Tree: true

Frequency: 1

Rarity: 4.0

RotateRandomly: true

SpawnHeight: highestSolidBlock

SpawnHeightOffset: 0

SpawnHeightVariance: 0

##############################
# Height Limits for the BO3. #
##############################

MinHeight: 62

MaxHeight: 65

######################
# Extrusion settings #
######################

ExtrudeMode: None

ExtrudeThroughBlocks: AIR

MaxBranchDepth: 10

ExcludedBiomes: All


#######################################################################
# +-----------------------------------------------------------------+ #
# |                      Source block settings                      | #
# +-----------------------------------------------------------------+ #
#######################################################################

SourceBlocks: AIR

MaxPercentageOutsideSourceBlock: 0

OutsideSourceBlock: placeAnyway

DoReplaceBlocks: true

IsOTGPlus: false


#######################################################################
# +-----------------------------------------------------------------+ #
# |                              Blocks                             | #
# +-----------------------------------------------------------------+ #
#######################################################################

Block(3,6,-3,biomesoplenty:log_1:15)
Block(-4,9,2,biomesoplenty:leaves_4:1)
Block(3,7,-3,biomesoplenty:log_1:15)
Block(3,9,-3,biomesoplenty:leaves_4:1)
Block(4,10,-3,biomesoplenty:leaves_4:1)
Block(3,10,-4,biomesoplenty:leaves_4:1)
Block(2,9,2,biomesoplenty:leaves_4:1)
Block(4,6,-3,biomesoplenty:leaves_4:1)
Block(4,9,-3,biomesoplenty:log_1:15)
Block(4,8,-3,biomesoplenty:log_1:15)
Block(-3,9,0,biomesoplenty:leaves_4:1)
Block(-1,10,1,biomesoplenty:leaves_4:1)
Block(5,10,-2,biomesoplenty:leaves_4:1)
Block(-1,5,-3,biomesoplenty:leaves_4:1)
Block(3,8,0,biomesoplenty:leaves_4:1)
Block(-1,6,0,biomesoplenty:leaves_4:1)
Block(-1,9,0,biomesoplenty:leaves_4:1)
Block(-2,8,2,biomesoplenty:leaves_4:1)
Block(5,5,-3,biomesoplenty:leaves_4:1)
Block(4,9,2,biomesoplenty:leaves_4:1)
Block(5,9,-3,biomesoplenty:leaves_4:1)
Block(2,5,-3,biomesoplenty:leaves_4:1)
Block(5,8,-3,COCOA:9)
Block(2,8,-3,biomesoplenty:leaves_4:1)
Block(0,5,-1,biomesoplenty:log_1:15)
Block(3,6,-2,biomesoplenty:leaves_4:1)
Block(6,9,-1,biomesoplenty:leaves_4:1)
Block(0,6,-1,biomesoplenty:log_1:15)
Block(1,7,1,biomesoplenty:leaves_4:1)
Block(3,10,-2,biomesoplenty:leaves_4:1)
Block(6,9,-5,biomesoplenty:leaves_4:1)
Block(-1,10,-1,biomesoplenty:leaves_4:1)
Block(4,8,-2,COCOA:10)
Block(4,9,-2,biomesoplenty:leaves_4:1)
Block(5,10,-4,biomesoplenty:leaves_4:1)
Block(-1,6,-2,biomesoplenty:leaves_4:1)
Block(3,7,1,biomesoplenty:log_1:15)
Block(3,6,1,biomesoplenty:log_1:15)
Block(-4,9,-2,biomesoplenty:leaves_4:1)
Block(3,9,1,biomesoplenty:leaves_4:1)
Block(3,8,1,biomesoplenty:log_1:15)
Block(-2,9,1,biomesoplenty:leaves_4:1)
Block(-2,8,1,COCOA:10)
Block(-3,5,-1,biomesoplenty:leaves_4:1)
Block(2,4,-4,biomesoplenty:leaves_4:1)
Block(5,7,1,biomesoplenty:leaves_4:1)
Block(0,9,2,biomesoplenty:leaves_4:1)
Block(0,4,-2,biomesoplenty:leaves_4:1)
Block(3,7,-1,biomesoplenty:leaves_4:1)
Block(3,5,-5,biomesoplenty:leaves_4:1)
Block(0,9,-2,biomesoplenty:leaves_4:1)
Block(-4,8,0,biomesoplenty:leaves_4:1)
Block(-2,10,0,biomesoplenty:leaves_4:1)
Block(4,8,-5,biomesoplenty:leaves_4:1)
Block(-2,9,-1,biomesoplenty:leaves_4:1)
Block(2,6,0,biomesoplenty:log_1:15)
Block(4,8,-1,biomesoplenty:leaves_4:1)
Block(2,9,0,biomesoplenty:leaves_4:1)
Block(1,5,-2,biomesoplenty:leaves_4:1)
Block(-2,6,-1,biomesoplenty:leaves_4:1)
Block(-1,7,-1,biomesoplenty:log_1:15)
Block(-1,6,-1,biomesoplenty:log_1:15)
Block(3,8,2,biomesoplenty:leaves_4:1)
Block(3,7,2,COCOA:10)
Block(-2,9,0,biomesoplenty:log_1:15)
Block(-2,8,0,biomesoplenty:log_1:15)
Block(2,1,-1,biomesoplenty:log_1:15)
Block(2,0,-1,biomesoplenty:log_1:15)
Block(4,7,0,biomesoplenty:leaves_4:1)
Block(4,9,0,biomesoplenty:leaves_4:1)
Block(5,8,-1,biomesoplenty:leaves_4:1)
Block(2,3,-1,biomesoplenty:log_1:15)
Block(2,2,-1,biomesoplenty:log_1:15)
Block(2,9,-1,biomesoplenty:leaves_4:1)
Block(-3,10,-1,biomesoplenty:leaves_4:1)
Block(2,9,-5,biomesoplenty:leaves_4:1)
Block(3,6,-4,biomesoplenty:leaves_4:1)
Block(-3,10,1,biomesoplenty:leaves_4:1)
Block(1,8,3,biomesoplenty:leaves_4:1)
Block(6,8,-3,biomesoplenty:leaves_4:1)
Block(4,9,-4,biomesoplenty:leaves_4:1)
Block(-2,8,-2,biomesoplenty:leaves_4:1)
Block(1,8,-1,biomesoplenty:leaves_4:1)
Block(1,5,-1,biomesoplenty:log_1:15)
Block(2,8,1,biomesoplenty:leaves_4:1)
Block(1,3,-1,biomesoplenty:log_1:15)
Block(1,4,-1,biomesoplenty:log_1:15)
Block(-1,5,1,biomesoplenty:leaves_4:1)
Block(3,7,3,biomesoplenty:leaves_4:1)
Block(2,5,0,biomesoplenty:log_1:15)
Block(4,8,1,biomesoplenty:leaves_4:1)
Block(4,7,1,COCOA:9)
Block(5,8,3,biomesoplenty:leaves_4:1)
Block(0,8,0,biomesoplenty:leaves_4:1)
Block(2,6,-2,biomesoplenty:log_1:15)
Block(2,5,-2,biomesoplenty:log_1:15)

#######################################################################
# +-----------------------------------------------------------------+ #
# |                            BO3 checks                           | #
# +-----------------------------------------------------------------+ #
#######################################################################


#######################################################################
# +-----------------------------------------------------------------+ #
# |                             Branches                            | #
# +-----------------------------------------------------------------+ #
#######################################################################


#######################################################################
# +-----------------------------------------------------------------+ #
# |                             Entities                            | #
# +-----------------------------------------------------------------+ #
#######################################################################


#######################################################################
# +-----------------------------------------------------------------+ #
# |                            Particles                            | #
# +-----------------------------------------------------------------+ #
#######################################################################


#######################################################################
# +-----------------------------------------------------------------+ #
# |                             Spawners                            | #
# +-----------------------------------------------------------------+ #
#######################################################################


#######################################################################
# +-----------------------------------------------------------------+ #
# |                             ModData                             | #
# +-----------------------------------------------------------------+ #
#######################################################################

