
#######################################################################
# +-----------------------------------------------------------------+ #
# |                            BO3 object                           | #
# +-----------------------------------------------------------------+ #
#######################################################################

Author: Unknown

Description: Converted version of the BO2 JunglePalm11

Version: 3

SettingsMode: WriteWithoutComments


#######################################################################
# +-----------------------------------------------------------------+ #
# |                          Main settings                          | #
# +-----------------------------------------------------------------+ #
#######################################################################

Tree: true

Frequency: 1

Rarity: 4.0

RotateRandomly: true

SpawnHeight: highestSolidBlock

SpawnHeightOffset: 0

SpawnHeightVariance: 0

##############################
# Height Limits for the BO3. #
##############################

MinHeight: 62

MaxHeight: 65

######################
# Extrusion settings #
######################

ExtrudeMode: None

ExtrudeThroughBlocks: AIR

MaxBranchDepth: 10

ExcludedBiomes: All


#######################################################################
# +-----------------------------------------------------------------+ #
# |                      Source block settings                      | #
# +-----------------------------------------------------------------+ #
#######################################################################

SourceBlocks: AIR

MaxPercentageOutsideSourceBlock: 0

OutsideSourceBlock: placeAnyway

DoReplaceBlocks: true

IsOTGPlus: false


#######################################################################
# +-----------------------------------------------------------------+ #
# |                              Blocks                             | #
# +-----------------------------------------------------------------+ #
#######################################################################

Block(0,1,2,biomesoplenty:log_1:15)
Block(-5,11,-3,biomesoplenty:leaves_4:1)
Block(-3,7,4,biomesoplenty:log_1:15)
Block(-7,8,3,biomesoplenty:leaves_4:1)
Block(-3,6,0,biomesoplenty:log_1:15)
Block(0,-1,5,biomesoplenty:log_1:15)
Block(-3,9,0,biomesoplenty:leaves_4:1)
Block(0,10,-4,biomesoplenty:leaves_4:1)
Block(-7,9,3,biomesoplenty:leaves_4:1)
Block(-1,11,1,biomesoplenty:leaves_4:1)
Block(-3,5,0,biomesoplenty:log_1:15)
Block(-3,4,0,biomesoplenty:log_1:15)
Block(-7,8,-5,biomesoplenty:leaves_4:1)
Block(-7,9,-5,biomesoplenty:leaves_4:1)
Block(-2,8,2,biomesoplenty:leaves_4:1)
Block(-2,7,2,biomesoplenty:leaves_4:1)
Block(-2,6,2,biomesoplenty:log_1:15)
Block(-2,5,2,biomesoplenty:log_1:15)
Block(1,-1,5,biomesoplenty:log_1:15)
Block(-3,8,-2,AIR)
Block(-3,9,-2,biomesoplenty:leaves_4:1)
Block(-3,10,5,biomesoplenty:leaves_4:1)
Block(1,0,3,biomesoplenty:log_1:15)
Block(1,8,5,biomesoplenty:leaves_4:1)
Block(1,7,5,biomesoplenty:leaves_4:1)
Block(0,9,-1,biomesoplenty:leaves_4:1)
Block(0,8,-1,biomesoplenty:leaves_4:1)
Block(-4,9,5,biomesoplenty:leaves_4:1)
Block(-3,10,-3,biomesoplenty:leaves_4:1)
Block(-6,9,-1,biomesoplenty:leaves_4:1)
Block(-6,8,-1,biomesoplenty:leaves_4:1)
Block(-6,10,-4,biomesoplenty:leaves_4:1)
Block(-1,10,-1,biomesoplenty:leaves_4:1)
Block(1,-1,6,biomesoplenty:log_1:15)
Block(-3,6,3,biomesoplenty:log_1:15)
Block(-4,9,-2,AIR)
Block(-2,9,5,biomesoplenty:leaves_4:1)
Block(-1,10,5,biomesoplenty:leaves_4:1)
Block(-2,8,5,biomesoplenty:log_1:15)
Block(-2,5,1,biomesoplenty:log_1:15)
Block(-2,4,1,biomesoplenty:log_1:15)
Block(-2,3,1,biomesoplenty:log_1:15)
Block(-2,10,4,biomesoplenty:leaves_4:1)
Block(-3,6,-1,biomesoplenty:log_1:15)
Block(-3,7,-1,biomesoplenty:log_1:15)
Block(-3,8,-1,biomesoplenty:log_1:15)
Block(-3,9,-1,biomesoplenty:log_1:15)
Block(1,0,4,biomesoplenty:log_1:15)
Block(-2,10,-2,biomesoplenty:leaves_4:1)
Block(-2,11,0,biomesoplenty:leaves_4:1)
Block(-2,10,0,biomesoplenty:leaves_4:1)
Block(-2,9,-1,biomesoplenty:leaves_4:1)
Block(-1,11,-3,biomesoplenty:leaves_4:1)
Block(-5,11,1,biomesoplenty:leaves_4:1)
Block(-3,9,2,biomesoplenty:leaves_4:1)
Block(-3,8,2,biomesoplenty:leaves_4:1)
Block(-1,2,2,biomesoplenty:log_1:15)
Block(-2,8,8,biomesoplenty:leaves_4:1)
Block(-2,7,8,biomesoplenty:leaves_4:1)
Block(-4,9,-1,biomesoplenty:leaves_4:1)
Block(-2,9,4,AIR)
Block(2,-3,7,biomesoplenty:log_1:15)
Block(-2,10,6,biomesoplenty:leaves_4:1)
Block(-5,8,5,biomesoplenty:leaves_4:1)
Block(-5,7,5,biomesoplenty:leaves_4:1)
Block(-4,10,0,biomesoplenty:leaves_4:1)
Block(-4,11,0,biomesoplenty:leaves_4:1)
Block(1,0,5,biomesoplenty:log_1:15)
Block(-3,8,-4,biomesoplenty:leaves_4:1)
Block(-3,10,-1,biomesoplenty:leaves_4:1)
Block(0,10,2,biomesoplenty:leaves_4:1)
Block(-3,9,-4,biomesoplenty:leaves_4:1)
Block(-4,11,-2,biomesoplenty:leaves_4:1)
Block(-4,10,-2,biomesoplenty:leaves_4:1)
Block(0,9,5,biomesoplenty:leaves_4:1)
Block(2,-3,6,biomesoplenty:log_1:15)
Block(2,-2,6,biomesoplenty:log_1:15)
Block(1,9,3,biomesoplenty:leaves_4:1)
Block(-3,10,1,biomesoplenty:leaves_4:1)
Block(1,8,3,biomesoplenty:leaves_4:1)
Block(0,1,3,biomesoplenty:log_1:15)
Block(-5,10,-1,biomesoplenty:leaves_4:1)
Block(1,9,-5,biomesoplenty:leaves_4:1)
Block(1,8,-5,biomesoplenty:leaves_4:1)
Block(-2,11,5,biomesoplenty:leaves_4:1)
Block(-2,10,5,biomesoplenty:leaves_4:1)
Block(-6,10,2,biomesoplenty:leaves_4:1)
Block(-2,9,7,biomesoplenty:leaves_4:1)
Block(-2,9,3,biomesoplenty:leaves_4:1)
Block(-1,8,5,AIR)
Block(-2,11,-2,biomesoplenty:leaves_4:1)
Block(-1,2,1,biomesoplenty:log_1:15)

#######################################################################
# +-----------------------------------------------------------------+ #
# |                            BO3 checks                           | #
# +-----------------------------------------------------------------+ #
#######################################################################


#######################################################################
# +-----------------------------------------------------------------+ #
# |                             Branches                            | #
# +-----------------------------------------------------------------+ #
#######################################################################


#######################################################################
# +-----------------------------------------------------------------+ #
# |                             Entities                            | #
# +-----------------------------------------------------------------+ #
#######################################################################


#######################################################################
# +-----------------------------------------------------------------+ #
# |                            Particles                            | #
# +-----------------------------------------------------------------+ #
#######################################################################


#######################################################################
# +-----------------------------------------------------------------+ #
# |                             Spawners                            | #
# +-----------------------------------------------------------------+ #
#######################################################################


#######################################################################
# +-----------------------------------------------------------------+ #
# |                             ModData                             | #
# +-----------------------------------------------------------------+ #
#######################################################################

